<?xml version="1.0" ?>
<!-- =================================================================================== -->
<!-- |    This document was autogenerated by xacro from urdf/olv-owl01.urdf            | -->
<!-- |    EDITING THIS FILE BY HAND IS NOT RECOMMENDED                                 | -->
<!-- =================================================================================== -->
<robot name="olv-owl01">
  <link name="olv_srv01_base_link">
    <visual>
      <geometry>
        <mesh filename="package://olive_components_description/meshes/olv-srv01.dae"/>
      </geometry>
    </visual>
    <collision>
      <geometry>
        <box size="0.06 0.06 0.046"/>
      </geometry>
    </collision>
  </link>
  <link name="base_link">
    <visual>
      <geometry>
        <mesh filename="package://olive_owl_description/meshes/olv-owl01-lbracket.dae"/>
      </geometry>
    </visual>
    <collision>
      <geometry>
        <box size="0.046 0.055 0.078"/>
      </geometry>
      <origin rpy="0 0 0" xyz="0 0.008 0.039"/>
    </collision>
  </link>
  <joint name="test_joint" type="continuous">
    <parent link="base_link"/>
    <child link="olv_srv01_base_link"/>
    <origin rpy="-1.57 0 0" xyz="0.0 0.08 0.023"/>
    <axis xyz="0 0 1"/>
  </joint>
</robot>
